<?xml version="1.0" ?>
<!-- =================================================================================== -->
<!-- |    This document was autogenerated by xacro from /home/li/ROS/probot_ws/src/PROBOT_Anno/probot_description/urdf/probot_anno_with_camera.xacro | -->
<!-- |    EDITING THIS FILE BY HAND IS NOT RECOMMENDED                                 | -->
<!-- =================================================================================== -->
<robot name="probot_anno" xmlns:xacro="http://ros.org/wiki/xacro">
    <!-- Put all the color definitions in a separate file -->
    <material name="Black">
        <color rgba="0.2 0.2 0.2 1.0" />
    </material>
    <material name="TransparentBlack">
        <color rgba="0.2 0.2 0.2 0.8" />
    </material>
    <material name="Orange">
        <color rgba="1.0  0.55 0.0 1.0" />
    </material>
    <material name="Grey">
        <color rgba="0.7 0.7 0.7 1.0" />
    </material>
    <material name="DarkGrey">
        <color rgba="0.3 0.3 0.3 1.0" />
    </material>
    <material name="Red">
        <color rgba="0.8 0.0 0.0 1.0" />
    </material>
    <material name="White">
        <color rgba="1.0 1.0 1.0 1.0" />
    </material>
    <material name="OffWhite">
        <color rgba="0.8 0.8 0.8 1.0" />
    </material>
    <material name="Blue">
        <color rgba="0.0 0.0 0.8 1.0" />
    </material>
    <material name="Green">
        <color rgba="0.0 0.8 0.0 1.0" />
    </material>
    <material name="TransparentGreen">
        <color rgba="0.0 0.8 0.0 0.5" />
    </material>
    <!-- <xacro:include filename="$(find robotiq_2f_c2_gripper_visualization)/urdf/robotiq_c2_model_macro.xacro" />
  <xacro:robotiq_c2_model prefix=""/> -->
    <link name="world" static="true" />
    <joint name="joint_0" type="fixed">
        <origin rpy="0 0 0" xyz="0.0 0 0.03" />
        <parent link="world" />
        <child link="base_link" />
    </joint>
    <link name="base_link">
        
<inertial>
            <origin rpy="0 0 0" xyz="-0.010934 0.23134 0.0051509" />
            <mass value="4.0" />
            <inertia ixx="0.0061063308908" ixy="0.0" ixz="0.0" iyy="0.0061063308908" iyz="0.0" izz="0.01125" />
            <!-- <mass value="0.01" />
      <inertia ixx="1.0" ixy="0.0" ixz="0.0" iyy="1.0" iyz="0.0" izz="1.0" /> -->
        </inertial>

        <visual>
            <origin rpy="0 0 0" xyz="0.017266 0 0.0315" />
            <geometry>
                <mesh filename="package://probot_description/meshes/PROBOT_Anno/base_link.STL" />
            </geometry>
            <material name="">
                <color rgba="0.79216 0.81961 0.93333 1" />
            </material>
        </visual>
        <collision>
            <origin rpy="0 0 0" xyz="0.017266 0 0.0315" />
            <geometry>
                <mesh filename="package://probot_description/meshes/PROBOT_Anno/base_link.STL" />
            </geometry>
        </collision>
    </link>
    <gazebo reference="base_link">
        <static>true</static>
        <implicitSpringDamper>1</implicitSpringDamper>
        <material>Gazebo/White</material>
        <mu1>100000</mu1>
        <mu2>100000</mu2>
        <kp>10000.0</kp>
        <kd>1.0</kd>
    </gazebo>
    <link name="link_1">
        
<inertial>
            <origin rpy="0 0 0" xyz="-0.010934 0.23134 0.0051509" />
            <mass value="7.778" />
            <inertia ixx="0.0314743125769" ixy="0.0" ixz="0.0" iyy="0.0314743125769" iyz="0.0" izz="0.021875625" />
            <!-- <mass value="0.01" />
      <inertia ixx="1.0" ixy="0.0" ixz="0.0" iyy="1.0" iyz="0.0" izz="1.0" /> -->
        </inertial>

        <visual>
            <origin rpy="0 0 0" xyz="0 0 0" />
            <geometry>
                <mesh filename="package://probot_description/meshes/PROBOT_Anno/link_1.STL" />
            </geometry>
            <material name="">
                <color rgba="0.79216 0.81961 0.93333 1" />
            </material>
        </visual>
        <collision>
            <origin rpy="0 0 0" xyz="0 0 0" />
            <geometry>
                <mesh filename="package://probot_description/meshes/PROBOT_Anno/link_1.STL" />
            </geometry>
        </collision>
    </link>
    <joint name="joint_1" type="revolute">
        <origin rpy="1.5708 0 0" xyz="0 0 0.0315" />
        <parent link="base_link" />
        <child link="link_1" />
        <axis xyz="0 1 0" />
        <limit effort="100" lower="-3.1416" upper="3.1416" velocity="3" />
    </joint>
    <link name="link_2">
        
<inertial>
            <origin rpy="0 0 0" xyz="-0.010934 0.23134 0.0051509" />
            <mass value="12.93" />
            <inertia ixx="0.421753803798" ixy="0.0" ixz="0.0" iyy="0.421753803798" iyz="0.0" izz="0.036365625" />
            <!-- <mass value="0.001" />
        <inertia ixx="1.0" ixy="0.0" ixz="0.0" iyy="1.0" iyz="0.0" izz="1.0" /> -->
        </inertial>

        <visual>
            <origin rpy="0 0 0" xyz="0 0 0" />
            <geometry>
                <mesh filename="package://probot_description/meshes/PROBOT_Anno/link_2.STL" />
            </geometry>
            <material name="">
                <color rgba="0.79216 0.81961 0.93333 1" />
            </material>
        </visual>
        <collision>
            <origin rpy="0 0 0" xyz="0 0 0" />
            <geometry>
                <mesh filename="package://probot_description/meshes/PROBOT_Anno/link_2.STL" />
            </geometry>
        </collision>
    </link>
    <joint name="joint_2" type="revolute">
        <origin rpy="0 0 0" xyz="0 0.2305 0" />
        <parent link="link_1" />
        <child link="link_2" />
        <axis xyz="0 0 1" />
        <limit effort="100" lower="-2.0071" upper="2.0071" velocity="3" />
    </joint>
    <link name="link_3">
        
<inertial>
            <origin rpy="0 0 0" xyz="-0.010934 0.23134 0.0051509" />
            <mass value="3.87" />
            <inertia ixx="0.111069694097" ixy="0.0" ixz="0.0" iyy="0.111069694097" iyz="0.0" izz="0.010884375" />
            <!-- <mass value="0.001" />
        <inertia ixx="1.0" ixy="0.0" ixz="0.0" iyy="1.0" iyz="0.0" izz="1.0" /> -->
        </inertial>

        <visual>
            <origin rpy="0 0 0" xyz="0 0 0" />
            <geometry>
                <mesh filename="package://probot_description/meshes/PROBOT_Anno/link_3.STL" />
            </geometry>
            <material name="">
                <color rgba="0.79216 0.81961 0.93333 1" />
            </material>
        </visual>
        <collision>
            <origin rpy="0 0 0" xyz="0 0 0" />
            <geometry>
                <mesh filename="package://probot_description/meshes/PROBOT_Anno/link_3.STL" />
            </geometry>
        </collision>
    </link>
    <joint name="joint_3" type="revolute">
        <origin rpy="0 0 0" xyz="0 0.225 0" />
        <parent link="link_2" />
        <child link="link_3" />
        <axis xyz="0 0 1" />
        <limit effort="100" lower="-0.6981" upper="3.8397" velocity="3" />
    </joint>
    <link name="link_4">
        
<inertial>
            <origin rpy="0 0 0" xyz="-0.010934 0.23134 0.0051509" />
            <mass value="1.96" />
            <inertia ixx="0.0051082479567" ixy="0.0" ixz="0.0" iyy="0.0051082479567" iyz="0.0" izz="0.0055125" />
            <!-- <mass value="0.00001" />
      <inertia ixx="1.0" ixy="0.0" ixz="0.0" iyy="1.0" iyz="0.0" izz="1.0" /> -->
        </inertial>

        <visual>
            <origin rpy="0 0 0" xyz="0 0 0" />
            <geometry>
                <mesh filename="package://probot_description/meshes/PROBOT_Anno/link_4.STL" />
            </geometry>
            <material name="">
                <color rgba="0.79216 0.81961 0.93333 1" />
            </material>
        </visual>
        <collision>
            <origin rpy="0 0 0" xyz="0 0 0" />
            <geometry>
                <mesh filename="package://probot_description/meshes/PROBOT_Anno/link_4.STL" />
            </geometry>
        </collision>
    </link>
    <joint name="joint_4" type="revolute">
        <origin rpy="0 0 0" xyz="0.023 0 0.0" />
        <parent link="link_3" />
        <child link="link_4" />
        <axis xyz="1 0 0" />
        <limit effort="100" lower="-3.1416" upper="3.1416" velocity="3" />
    </joint>
    <link name="link_5">
        
<inertial>
            <origin rpy="0 0 0" xyz="-0.010934 0.23134 0.0051509" />
            <mass value="1.96" />
            <inertia ixx="0.0051082479567" ixy="0.0" ixz="0.0" iyy="0.0051082479567" iyz="0.0" izz="0.0055125" />
            <!-- <mass value="0.00001" />
      <inertia ixx="1.0" ixy="0.0" ixz="0.0" iyy="1.0" iyz="0.0" izz="1.0" /> -->
        </inertial>

        <visual>
            <origin rpy="0 0 0" xyz="0 0 0" />
            <geometry>
                <mesh filename="package://probot_description/meshes/PROBOT_Anno/link_5.STL" />
            </geometry>
            <material name="">
                <color rgba="0.79216 0.81961 0.93333 1" />
            </material>
        </visual>
        <collision>
            <origin rpy="0 0 0" xyz="0 0 0" />
            <geometry>
                <mesh filename="package://probot_description/meshes/PROBOT_Anno/link_5.STL" />
            </geometry>
        </collision>
    </link>
    <joint name="joint_5" type="revolute">
        <origin rpy="0 0 0" xyz="0.20585535 0 0" />
        <parent link="link_4" />
        <child link="link_5" />
        <axis xyz="0 0 1" />
        <limit effort="100" lower="-0.7854" upper="3.9270" velocity="3" />
    </joint>
    <link name="link_6">
        
<inertial>
            <origin rpy="0 0 0" xyz="-0.010934 0.23134 0.0051509" />
            <mass value="0.202" />
            <inertia ixx="0.000526462289415" ixy="0.0" ixz="0.0" iyy="0.000526462289415" iyz="0.0" izz="0.000568125" />
            <!-- <mass value="0.00001" />
      <inertia ixx="1.0" ixy="0.0" ixz="0.0" iyy="1.0" iyz="0.0" izz="1.0" /> -->
        </inertial>

        <visual>
            <origin rpy="0 0 0" xyz="0 0 0" />
            <geometry>
                <mesh filename="package://probot_description/meshes/PROBOT_Anno/link_6.STL" />
            </geometry>
            <material name="">
                <color rgba="0.79216 0.81961 0.93333 1" />
            </material>
        </visual>
        <collision>
            <origin rpy="0 0 0" xyz="0 0 0" />
            <geometry>
                <mesh filename="package://probot_description/meshes/PROBOT_Anno/link_6.STL" />
            </geometry>
        </collision>
    </link>
    <joint name="joint_6" type="revolute">
        <origin rpy="0 0 0" xyz="0 -0.042 0" />
        <parent link="link_5" />
        <child link="link_6" />
        <axis xyz="0 -1 0" />
        <limit effort="100" lower="-3.1416" upper="3.1416" velocity="3" />
    </joint>
    <link name="tool0" />
    <joint name="joint_tool0" type="fixed">
        <origin rpy="1.5707963268 0 0" xyz="0 -0.013 0" />
        <parent link="link_6" />
        <child link="tool0" />
    </joint>
    <!-- Attach the right gripper -->
    <!-- <gripper parent="tool0" color="Green" xyz="0 0.015 0.02" rpy="0 ${-M_PI/2} ${-M_PI/2}"/> -->
    <!-- Grasping frame -->
    <link name="grasping_frame" />
    <joint name="grasping_frame_joint" type="fixed">
        <parent link="tool0" />
        <child link="grasping_frame" />
        <origin rpy="0 0 0" xyz="0.0 0 0.01" />
    </joint>
    <transmission name="tran1">
        <type>transmission_interface/SimpleTransmission</type>
        <joint name="joint_1">
            <hardwareInterface>hardware_interface/PositionJointInterface</hardwareInterface>
        </joint>
        <actuator name="joint_1_joint">
            <hardwareInterface>hardware_interface/PositionJointInterface</hardwareInterface>
            <mechanicalReduction>1</mechanicalReduction>
        </actuator>
    </transmission>
    <transmission name="tran1">
        <type>transmission_interface/SimpleTransmission</type>
        <joint name="joint_2">
            <hardwareInterface>hardware_interface/PositionJointInterface</hardwareInterface>
        </joint>
        <actuator name="joint_2_joint">
            <hardwareInterface>hardware_interface/PositionJointInterface</hardwareInterface>
            <mechanicalReduction>1</mechanicalReduction>
        </actuator>
    </transmission>
    <transmission name="tran1">
        <type>transmission_interface/SimpleTransmission</type>
        <joint name="joint_3">
            <hardwareInterface>hardware_interface/PositionJointInterface</hardwareInterface>
        </joint>
        <actuator name="joint_3_joint">
            <hardwareInterface>hardware_interface/PositionJointInterface</hardwareInterface>
            <mechanicalReduction>1</mechanicalReduction>
        </actuator>
    </transmission>
    <transmission name="tran1">
        <type>transmission_interface/SimpleTransmission</type>
        <joint name="joint_4">
            <hardwareInterface>hardware_interface/PositionJointInterface</hardwareInterface>
        </joint>
        <actuator name="joint_4_joint">
            <hardwareInterface>hardware_interface/PositionJointInterface</hardwareInterface>
            <mechanicalReduction>1</mechanicalReduction>
        </actuator>
    </transmission>
    <transmission name="tran1">
        <type>transmission_interface/SimpleTransmission</type>
        <joint name="joint_5">
            <hardwareInterface>hardware_interface/PositionJointInterface</hardwareInterface>
        </joint>
        <actuator name="joint_5_joint">
            <hardwareInterface>hardware_interface/PositionJointInterface</hardwareInterface>
            <mechanicalReduction>1</mechanicalReduction>
        </actuator>
    </transmission>
    <transmission name="tran1">
        <type>transmission_interface/SimpleTransmission</type>
        <joint name="joint_6">
            <hardwareInterface>hardware_interface/PositionJointInterface</hardwareInterface>
        </joint>
        <actuator name="joint_6_joint">
            <hardwareInterface>hardware_interface/PositionJointInterface</hardwareInterface>
            <mechanicalReduction>1</mechanicalReduction>
        </actuator>
    </transmission>
    <joint name="camera_joint" type="fixed">
        <origin rpy="0 1.5707963268 0" xyz="0.3 0 0.7" />
        <parent link="base_link" />
        <child link="camera_link" />
    </joint>
    <!-- Camera -->
    <link name="camera_link">
        <collision>
            <origin rpy="0 0 0" xyz="0 0 0" />
            <geometry>
                <mesh filename="package://probot_description/meshes/sensors/camera.STL" />
            </geometry>
        </collision>
        <visual>
            <origin rpy="-3.1415926536 0 -1.5707963268" xyz="0 0 0" />
            <geometry>
                <mesh filename="package://probot_description/meshes/sensors/camera.STL" />
            </geometry>
            <material name="red" />
        </visual>
        
<inertial>
            <mass value="0.00001" />
            <origin xyz="0 0 0" />
            <inertia ixx="1.0" ixy="0.0" ixz="0.0" iyy="1.0" iyz="0.0" izz="1.0" />
        </inertial>

    </link>
    <!-- camera -->
    <gazebo reference="camera_link">
        <material>Gazebo/Red</material>
        <sensor name="camera" type="camera">
            <update_rate>30.0</update_rate>
            <camera name="head">
                <horizontal_fov>1.3</horizontal_fov>
                <!-- <horizontal_fov>0.95</horizontal_fov> -->
                <image>
                    <width>800</width>
                    <height>800</height>
                    <format>R8G8B8</format>
                </image>
                <clip>
                    <near>0.02</near>
                    <far>300</far>
                </clip>
                <noise>
                    <type>gaussian</type>
                    <!-- Noise is sampled independently per pixel on each frame.
               That pixel's noise value is added to each of its color
               channels, which at that point lie in the range [0,1]. -->
                    <mean>0.0</mean>
                    <stddev>0.007</stddev>
                </noise>
            </camera>
            <plugin filename="libgazebo_ros_camera.so" name="camera_controller">
                <alwaysOn>true</alwaysOn>
                <updateRate>0.0</updateRate>
                <cameraName>probot_anno/camera</cameraName>
                <imageTopicName>image_raw</imageTopicName>
                <cameraInfoTopicName>camera_info</cameraInfoTopicName>
                <frameName>camera_link</frameName>
                <hackBaseline>0.07</hackBaseline>
                <distortionK1>0.0</distortionK1>
                <distortionK2>0.0</distortionK2>
                <distortionK3>0.0</distortionK3>
                <distortionT1>0.0</distortionT1>
                <distortionT2>0.0</distortionT2>
            </plugin>
        </sensor>
    </gazebo>
    <joint name="hand_camera_joint" type="fixed">
        <origin rpy="0 -1.5707963268 3.1415926536" xyz="0.0 -0.033 0.015" />
        <parent link="tool0" />
        <child link="hand_camera_link" />
    </joint>
    <!-- Camera -->
    <link name="hand_camera_link">
        <collision>
            <origin rpy="-1.5707963268 1.5707963268 0" xyz="0 0 0" />
            <geometry>
                <mesh filename="package://probot_description/meshes/sensors/camera.STL" />
            </geometry>
        </collision>
        <visual>
            <origin rpy="-1.5707963268 1.5707963268 0" xyz="0 0 0" />
            <geometry>
                <mesh filename="package://probot_description/meshes/sensors/camera.STL" />
            </geometry>
            <material name="black" />
        </visual>
        
<inertial>
            <mass value="0.00001" />
            <origin xyz="0 0 0" />
            <inertia ixx="1.0" ixy="0.0" ixz="0.0" iyy="1.0" iyz="0.0" izz="1.0" />
        </inertial>

    </link>
    <!-- camera -->
    <gazebo reference="hand_camera_link">
        <material>Gazebo/Black</material>
        <sensor name="hand_camera" type="camera">
            <update_rate>30.0</update_rate>
            <camera name="hand">
                <horizontal_fov>1.3</horizontal_fov>
                <!-- <horizontal_fov>0.95</horizontal_fov> -->
                <image>
                    <width>800</width>
                    <height>800</height>
                    <format>R8G8B8</format>
                </image>
                <clip>
                    <near>0.02</near>
                    <far>300</far>
                </clip>
                <noise>
                    <type>gaussian</type>
                    <!-- Noise is sampled independently per pixel on each frame.
               That pixel's noise value is added to each of its color
               channels, which at that point lie in the range [0,1]. -->
                    <mean>0.0</mean>
                    <stddev>0.007</stddev>
                </noise>
            </camera>
            <plugin filename="libgazebo_ros_camera.so" name="hand_camera_controller">
                <alwaysOn>true</alwaysOn>
                <updateRate>0.0</updateRate>
                <cameraName>probot_anno/hand_camera</cameraName>
                <imageTopicName>hand_image_raw</imageTopicName>
                <cameraInfoTopicName>hand_camera_info</cameraInfoTopicName>
                <frameName>hand_camera_link</frameName>
                <hackBaseline>0.07</hackBaseline>
                <distortionK1>0.0</distortionK1>
                <distortionK2>0.0</distortionK2>
                <distortionK3>0.0</distortionK3>
                <distortionT1>0.0</distortionT1>
                <distortionT2>0.0</distortionT2>
            </plugin>
        </sensor>
    </gazebo>
    <!-- ros_control plugin -->
    <gazebo>
        <plugin filename="libgazebo_ros_control.so" name="gazebo_ros_control">
            <robotNamespace>/probot_anno</robotNamespace>
            <robotSimType>gazebo_ros_control/DefaultRobotHWSim</robotSimType>
            <legacyModeNS>true</legacyModeNS>
        </plugin>
    </gazebo>
    <transmission name="trans_joint_1">
        <type>transmission_interface/SimpleTransmission</type>
        <joint name="joint_1">
            <hardwareInterface>hardware_interface/EffortJointInterface</hardwareInterface>
        </joint>
        <actuator name="joint_1_motor">
            <hardwareInterface>hardware_interface/EffortJointInterface</hardwareInterface>
            <mechanicalReduction>1</mechanicalReduction>
        </actuator>
    </transmission>
    <transmission name="trans_joint_2">
        <type>transmission_interface/SimpleTransmission</type>
        <joint name="joint_2">
            <hardwareInterface>hardware_interface/EffortJointInterface</hardwareInterface>
        </joint>
        <actuator name="joint_2_motor">
            <hardwareInterface>hardware_interface/EffortJointInterface</hardwareInterface>
            <mechanicalReduction>1</mechanicalReduction>
        </actuator>
    </transmission>
    <transmission name="trans_joint_3">
        <type>transmission_interface/SimpleTransmission</type>
        <joint name="joint_3">
            <hardwareInterface>hardware_interface/EffortJointInterface</hardwareInterface>
        </joint>
        <actuator name="joint_3_motor">
            <hardwareInterface>hardware_interface/EffortJointInterface</hardwareInterface>
            <mechanicalReduction>1</mechanicalReduction>
        </actuator>
    </transmission>
    <transmission name="trans_joint_4">
        <type>transmission_interface/SimpleTransmission</type>
        <joint name="joint_4">
            <hardwareInterface>hardware_interface/EffortJointInterface</hardwareInterface>
        </joint>
        <actuator name="joint_4_motor">
            <hardwareInterface>hardware_interface/EffortJointInterface</hardwareInterface>
            <mechanicalReduction>1</mechanicalReduction>
        </actuator>
    </transmission>
    <transmission name="trans_joint_5">
        <type>transmission_interface/SimpleTransmission</type>
        <joint name="joint_5">
            <hardwareInterface>hardware_interface/EffortJointInterface</hardwareInterface>
        </joint>
        <actuator name="joint_5_motor">
            <hardwareInterface>hardware_interface/EffortJointInterface</hardwareInterface>
            <mechanicalReduction>1</mechanicalReduction>
        </actuator>
    </transmission>
    <transmission name="trans_joint_6">
        <type>transmission_interface/SimpleTransmission</type>
        <joint name="joint_6">
            <hardwareInterface>hardware_interface/EffortJointInterface</hardwareInterface>
        </joint>
        <actuator name="joint_6_motor">
            <hardwareInterface>hardware_interface/EffortJointInterface</hardwareInterface>
            <mechanicalReduction>1</mechanicalReduction>
        </actuator>
    </transmission>
    <gazebo>
        <plugin name="gazebo_ros_control" filename="libgazebo_ros_control.so">
            <robotNamespace>/</robotNamespace>
        </plugin>
    </gazebo>
</robot>

<transmission name="tran1">
        <type>transmission_interface/SimpleTransmission</type>
        <joint name="joint_1">
            <hardwareInterface>hardware_interface/PositionJointInterface</hardwareInterface>
        </joint>
        <actuator name="joint_1_joint">
            <hardwareInterface>hardware_interface/PositionJointInterface</hardwareInterface>
            <mechanicalReduction>1</mechanicalReduction>
        </actuator>
    </transmission>
    <transmission name="tran1">
        <type>transmission_interface/SimpleTransmission</type>
        <joint name="joint_2">
            <hardwareInterface>hardware_interface/PositionJointInterface</hardwareInterface>
        </joint>
        <actuator name="joint_2_joint">
            <hardwareInterface>hardware_interface/PositionJointInterface</hardwareInterface>
            <mechanicalReduction>1</mechanicalReduction>
        </actuator>
    </transmission>
    <transmission name="tran1">
        <type>transmission_interface/SimpleTransmission</type>
        <joint name="joint_3">
            <hardwareInterface>hardware_interface/PositionJointInterface</hardwareInterface>
        </joint>
        <actuator name="joint_3_joint">
            <hardwareInterface>hardware_interface/PositionJointInterface</hardwareInterface>
            <mechanicalReduction>1</mechanicalReduction>
        </actuator>
    </transmission>
    <transmission name="tran1">
        <type>transmission_interface/SimpleTransmission</type>
        <joint name="joint_4">
            <hardwareInterface>hardware_interface/PositionJointInterface</hardwareInterface>
        </joint>
        <actuator name="joint_4_joint">
            <hardwareInterface>hardware_interface/PositionJointInterface</hardwareInterface>
            <mechanicalReduction>1</mechanicalReduction>
        </actuator>
    </transmission>
    <transmission name="tran1">
        <type>transmission_interface/SimpleTransmission</type>
        <joint name="joint_5">
            <hardwareInterface>hardware_interface/PositionJointInterface</hardwareInterface>
        </joint>
        <actuator name="joint_5_joint">
            <hardwareInterface>hardware_interface/PositionJointInterface</hardwareInterface>
            <mechanicalReduction>1</mechanicalReduction>
        </actuator>
    </transmission>
    <transmission name="tran1">
        <type>transmission_interface/SimpleTransmission</type>
        <joint name="joint_6">
            <hardwareInterface>hardware_interface/PositionJointInterface</hardwareInterface>
        </joint>
        <actuator name="joint_6_joint">
            <hardwareInterface>hardware_interface/PositionJointInterface</hardwareInterface>
            <mechanicalReduction>1</mechanicalReduction>
        </actuator>
    </transmission>
    <joint name="camera_joint" type="fixed">
        <origin rpy="0 1.5707963268 0" xyz="0.3 0 0.7" />
        <parent link="base_link" />
        <child link="camera_link" />
    </joint>
    <!-- Camera -->
    <link name="camera_link">
        <collision>
            <origin rpy="0 0 0" xyz="0 0 0" />
            <geometry>
                <mesh filename="package://probot_description/meshes/sensors/camera.STL" />
            </geometry>
        </collision>
        <visual>
            <origin rpy="-3.1415926536 0 -1.5707963268" xyz="0 0 0" />
            <geometry>
                <mesh filename="package://probot_description/meshes/sensors/camera.STL" />
            </geometry>
            <material name="red" />
        </visual>
        <inertial>
            <mass value="0.00001" />
            <origin xyz="0 0 0" />
            <inertia ixx="1.0" ixy="0.0" ixz="0.0" iyy="1.0" iyz="0.0" izz="1.0" />
        </inertial>
    </link>
    <!-- camera -->
    <gazebo reference="camera_link">
        <material>Gazebo/Red</material>
        <sensor name="camera" type="camera">
            <update_rate>30.0</update_rate>
            <camera name="head">
                <horizontal_fov>1.3</horizontal_fov>
                <!-- <horizontal_fov>0.95</horizontal_fov> -->
                <image>
                    <width>800</width>
                    <height>800</height>
                    <format>R8G8B8</format>
                </image>
                <clip>
                    <near>0.02</near>
                    <far>300</far>
                </clip>
                <noise>
                    <type>gaussian</type>
                    <!-- Noise is sampled independently per pixel on each frame.
               That pixel's noise value is added to each of its color
               channels, which at that point lie in the range [0,1]. -->
                    <mean>0.0</mean>
                    <stddev>0.007</stddev>
                </noise>
            </camera>
            <plugin filename="libgazebo_ros_camera.so" name="camera_controller">
                <alwaysOn>true</alwaysOn>
                <updateRate>0.0</updateRate>
                <cameraName>probot_anno/camera</cameraName>
                <imageTopicName>image_raw</imageTopicName>
                <cameraInfoTopicName>camera_info</cameraInfoTopicName>
                <frameName>camera_link</frameName>
                <hackBaseline>0.07</hackBaseline>
                <distortionK1>0.0</distortionK1>
                <distortionK2>0.0</distortionK2>
                <distortionK3>0.0</distortionK3>
                <distortionT1>0.0</distortionT1>
                <distortionT2>0.0</distortionT2>
            </plugin>
        </sensor>
    </gazebo>
    <joint name="hand_camera_joint" type="fixed">
        <origin rpy="0 -1.5707963268 3.1415926536" xyz="0.0 -0.033 0.015" />
        <parent link="tool0" />
        <child link="hand_camera_link" />
    </joint>
    <!-- Camera -->
    <link name="hand_camera_link">
        <collision>
            <origin rpy="-1.5707963268 1.5707963268 0" xyz="0 0 0" />
            <geometry>
                <mesh filename="package://probot_description/meshes/sensors/camera.STL" />
            </geometry>
        </collision>
        <visual>
            <origin rpy="-1.5707963268 1.5707963268 0" xyz="0 0 0" />
            <geometry>
                <mesh filename="package://probot_description/meshes/sensors/camera.STL" />
            </geometry>
            <material name="black" />
        </visual>
        <inertial>
            <mass value="0.00001" />
            <origin xyz="0 0 0" />
            <inertia ixx="1.0" ixy="0.0" ixz="0.0" iyy="1.0" iyz="0.0" izz="1.0" />
        </inertial>
    </link>
    <!-- camera -->
    <gazebo reference="hand_camera_link">
        <material>Gazebo/Black</material>
        <sensor name="hand_camera" type="camera">
            <update_rate>30.0</update_rate>
            <camera name="hand">
                <horizontal_fov>1.3</horizontal_fov>
                <!-- <horizontal_fov>0.95</horizontal_fov> -->
                <image>
                    <width>800</width>
                    <height>800</height>
                    <format>R8G8B8</format>
                </image>
                <clip>
                    <near>0.02</near>
                    <far>300</far>
                </clip>
                <noise>
                    <type>gaussian</type>
                    <!-- Noise is sampled independently per pixel on each frame.
               That pixel's noise value is added to each of its color
               channels, which at that point lie in the range [0,1]. -->
                    <mean>0.0</mean>
                    <stddev>0.007</stddev>
                </noise>
            </camera>
            <plugin filename="libgazebo_ros_camera.so" name="hand_camera_controller">
                <alwaysOn>true</alwaysOn>
                <updateRate>0.0</updateRate>
                <cameraName>probot_anno/hand_camera</cameraName>
                <imageTopicName>hand_image_raw</imageTopicName>
                <cameraInfoTopicName>hand_camera_info</cameraInfoTopicName>
                <frameName>hand_camera_link</frameName>
                <hackBaseline>0.07</hackBaseline>
                <distortionK1>0.0</distortionK1>
                <distortionK2>0.0</distortionK2>
                <distortionK3>0.0</distortionK3>
                <distortionT1>0.0</distortionT1>
                <distortionT2>0.0</distortionT2>
            </plugin>
        </sensor>
    </gazebo>
    <!-- ros_control plugin -->
    <gazebo>
        <plugin filename="libgazebo_ros_control.so" name="gazebo_ros_control">
            <robotNamespace>/probot_anno</robotNamespace>
            <robotSimType>gazebo_ros_control/DefaultRobotHWSim</robotSimType>
            <legacyModeNS>true</legacyModeNS>
        </plugin>
    </gazebo>
    <transmission name="trans_joint_1">
        <type>transmission_interface/SimpleTransmission</type>
        <joint name="joint_1">
            <hardwareInterface>hardware_interface/EffortJointInterface</hardwareInterface>
        </joint>
        <actuator name="joint_1_motor">
            <hardwareInterface>hardware_interface/EffortJointInterface</hardwareInterface>
            <mechanicalReduction>1</mechanicalReduction>
        </actuator>
    </transmission>
    <transmission name="trans_joint_2">
        <type>transmission_interface/SimpleTransmission</type>
        <joint name="joint_2">
            <hardwareInterface>hardware_interface/EffortJointInterface</hardwareInterface>
        </joint>
        <actuator name="joint_2_motor">
            <hardwareInterface>hardware_interface/EffortJointInterface</hardwareInterface>
            <mechanicalReduction>1</mechanicalReduction>
        </actuator>
    </transmission>
    <transmission name="trans_joint_3">
        <type>transmission_interface/SimpleTransmission</type>
        <joint name="joint_3">
            <hardwareInterface>hardware_interface/EffortJointInterface</hardwareInterface>
        </joint>
        <actuator name="joint_3_motor">
            <hardwareInterface>hardware_interface/EffortJointInterface</hardwareInterface>
            <mechanicalReduction>1</mechanicalReduction>
        </actuator>
    </transmission>
    <transmission name="trans_joint_4">
        <type>transmission_interface/SimpleTransmission</type>
        <joint name="joint_4">
            <hardwareInterface>hardware_interface/EffortJointInterface</hardwareInterface>
        </joint>
        <actuator name="joint_4_motor">
            <hardwareInterface>hardware_interface/EffortJointInterface</hardwareInterface>
            <mechanicalReduction>1</mechanicalReduction>
        </actuator>
    </transmission>
    <transmission name="trans_joint_5">
        <type>transmission_interface/SimpleTransmission</type>
        <joint name="joint_5">
            <hardwareInterface>hardware_interface/EffortJointInterface</hardwareInterface>
        </joint>
        <actuator name="joint_5_motor">
            <hardwareInterface>hardware_interface/EffortJointInterface</hardwareInterface>
            <mechanicalReduction>1</mechanicalReduction>
        </actuator>
    </transmission>
    <transmission name="trans_joint_6">
        <type>transmission_interface/SimpleTransmission</type>
        <joint name="joint_6">
            <hardwareInterface>hardware_interface/EffortJointInterface</hardwareInterface>
        </joint>
        <actuator name="joint_6_motor">
            <hardwareInterface>hardware_interface/EffortJointInterface</hardwareInterface>
            <mechanicalReduction>1</mechanicalReduction>
        </actuator>
    </transmission>
    <gazebo>
        <plugin name="gazebo_ros_control" filename="libgazebo_ros_control.so">
            <robotNamespace>/</robotNamespace>
        </plugin>
    </gazebo>
</robot>
